Failure # 1 (occurred at 2023-04-13_09-52-32)
[36mray::ImplicitFunc.train()[39m (pid=2574, ip=172.31.24.208, repr=training)
  File "/home/ray/anaconda3/lib/python3.7/site-packages/ray/tune/trainable/trainable.py", line 368, in train
    raise skipped from exception_cause(skipped)
  File "/home/ray/anaconda3/lib/python3.7/site-packages/ray/tune/trainable/function_trainable.py", line 340, in entrypoint
    self._status_reporter.get_checkpoint(),
  File "/home/ray/anaconda3/lib/python3.7/site-packages/ray/tune/trainable/function_trainable.py", line 654, in _trainable_func
    output = fn()
  File "/home/ray/TCL_IDC.py", line 195, in training
  File "/cascade_transfer_learning_medical/model/CascadeNet.py", line 23, in load_conv
    map_location='cpu').module
  File "/home/ray/anaconda3/lib/python3.7/site-packages/torch/serialization.py", line 771, in load
    with _open_file_like(f, 'rb') as opened_file:
  File "/home/ray/anaconda3/lib/python3.7/site-packages/torch/serialization.py", line 270, in _open_file_like
    return _open_file(name_or_buffer, mode)
  File "/home/ray/anaconda3/lib/python3.7/site-packages/torch/serialization.py", line 251, in __init__
    super(_open_file, self).__init__(open(name, mode))
FileNotFoundError: [Errno 2] No such file or directory: '/cascade_transfer_learning_medical/model/sourcemodel/layer 4/trained model'
